Workbook

Sheet Conventions
A1: Conventions -- axes, angles and signs (copied from the app's code)
A2: Input (type here) | B2: Formula (do not edit) | C2: Generator marker | D2: Guard row (keep blank)
A4: Units
A5: Lengths m, masses t, forces kN, moments kNm, angles deg (inputs), rad/s^2.
A6: Weight = mass_t x |g| (kN, since t x m/s^2 = kN). Gravity is typed signed (-9.81) as authored; the calculation uses its magnitude. | B6: calculation/engine.py
A8: Axes (crane frame)
A9: x: horizontal in the boom plane, positive toward the boom tip (outreach).
A10: z: up. y: lateral, completing a right-handed x-y-z frame.
A11: The crane frame is the vessel frame (x forward, y port, z up) rotated about z by the crane slewing angle; a vessel-frame horizontal vector (vx, vy) is (cos s vx + sin s vy, -sin s vx + cos s vy) in the crane frame. | B11: calculation/vessel_frame.py _vessel_to_crane
A12: In-plane moments are about +y with M = x Fz - z Fx (a load's moment about the origin as the solver accumulates it: ld_m += -z Fx + x Fz). | B12: calculation/solver/crane_solver.py
A14: Boom angle and boom-local coordinates
A15: Boom angle theta is measured at the boom heel from +x toward +z.
A16: Boom-local u runs along the boom from the heel, w is normal to it (u rotated +90 deg toward +z), v is lateral (= y). Global position: x = x_heel + u cos theta - w sin theta, z = z_heel + u sin theta + w cos theta. | B16: calculation/solver/crane_solver.py rotate_boom_local_point
A17: Only body 'boom' rows use boom-local coordinates; other bodies are global. | B17: scripts/excel_workbook/reference.py (name-based rule 5)
A18: Hanging nodes hang straight down (-z) from their parent node: the scene hoist's hook by the tackle length, idle hooks by their hanging drop. | B18: calculation/rope_mass.py active_hook_positions
A20: Vessel attitude and accelerations
A21: Vessel pitch is positive bow-down, roll positive to starboard (intrinsic z-y-x). Gravity in the vessel frame: g (sin pitch, -sin roll cos pitch, -cos roll cos pitch) with g = |g|. | B21: calculation/vessel_frame.py gravity_in_vessel_frame
A22: Load acceleration k = g_vessel - a (a = vessel accelerations ax, ay, az), rotated into the crane frame by the slewing angle; the equivalent crane-frame accelerations are ax' = -kx, ay' = -ky, az' = -|g| - kz. | B22: calculation/vessel_frame.py crane_frame_motion
A23: Pitch and roll angular accelerations are rotated into the crane frame the same way: (roll', pitch') = rotate(roll, pitch). | B23: calculation/vessel_frame.py crane_frame_motion
A24: Mass load (inertia + weight), with dx = x - x_ref, dz = z - z_ref (vessel motion reference): Fx = -m (ax' + pitch' dz), Fz = -m (|g| + az' - pitch' dx), Fy = -m (ay' - roll' dz). Pitch acceleration is right-handed about +y, roll acceleration right-handed about +x. | B24: calculation/solver/crane_solver.py inertia_force; calculation/engine.py
A26: Wind
A27: Direction +X, -X, +Y or -Y is the direction the wind blows toward: +X wind pushes in +x. Any other text is treated as +X by the app (flagged on Checks). | B27: calculation/engine.py split_wind_speed_components
A28: Force = sign x 0.5 rho Cd A V^2 / 1000 (kN). X wind uses 'Area for X wind', Y wind uses 'Area for Y wind'. X wind: areas of body 'boom' are scaled by |sin theta|; Y wind: boom-local areas are (the in-plane solver and the out-of-plane pass test this differently; identical when boom areas are boom-local). | B28: calculation/solver/crane_solver.py _wind_fx; calculation/engine.py
A30: Hook load, offlead and sidelead
A31: Hook load (kN) acts at the hook node in -z. Offlead adds sin(offlead) x hook load in +x at the node the hook hangs from (its parent node; the hook itself if it has none); sidelead adds sin(sidelead) x hook load in +y at the scene hoist's support node (its hook node if the support is missing). | B31: calculation/solver/crane_solver.py _accumulate_loads; core/drawn_loads.py hook_load; calculation/engine.py; core/lead_channels.py
A33: Ropes
A34: Role 'solve' marks the boom-hoist rope: its tension is an unknown of the boom solve (the app's rope with tension_mode 'solve', published as 'boom_hoist'). Exactly one active solve rope is required; without one the app shows no results. | B34: calculation/solver/crane_solver.py
A35: Role 'fixed': the scene hoist's rope carries hook load / parts at the hook; an idle hoist's rope carries hook mass x (|g| + az') / parts. | B35: calculation/solver/crane_solver.py
A36: Rope self-weight: each segment's length x parts x linear mass is split half to each end node; the rest of the hoist's total rope length (spooled) sits at its spool node (the 'Spool node' flag replaces the app's rule 'node id contains winch'). The hoist row's linear mass is the one used. | B36: calculation/rope_mass.py rope_mass_at_nodes
A37: Split-block mode is not supported by this workbook.
A39: Reaction signs (as the app reports them)
A40: Fx, Fz and My of every support (heel point, hinges, platform base) are support reactions opposing the applied loads: weight gives positive Fz; a +X vessel acceleration gives positive Fx. | B40: scripts/excel_workbook/reference.py
A41: Possible app sign bug, replicated: platform base Fy and Mx carry the sign of the applied loads, not of the reaction (a +Y wind gives positive Fy, and Mx = -z Fy). | B41: scripts/excel_workbook/reference.py
A42: Possible app sign bug, replicated: heel_left behaves as the -Y side. heel_left = 0.5 total + M / boom width, heel_right = 0.5 total - M / boom width (Fz uses Mx, Fx uses Mz), with M the applied-load moment about the heel: Mx = y Fz - z Fy, Mz = x_rel Fy - y Fx. A mass at +Y loads heel_right. The heel moments include every mass and wind area of the crane. | B42: scripts/excel_workbook/reference.py; calculation/engine.py
A43: Pinned connections (heel, hinges) carry no moment.
A45: Out-of-plane pass
A46: Y loads are not part of the in-plane solve. Moments of the applied loads are taken about the support-group origins boom_heel (heel), front_base, rear_base and platform_heel (platform base): Mx = y Fz - (z - oz) Fy, Mz = (x - ox) Fy - y Fx. Rope self-weight and idle hook blocks sit at y = 0; wind and the side force at y = 0. | B46: calculation/engine.py _out_of_plane_variants
A47: The side force acts at the support node's kinematic position (before the tackle moves the hook). | B47: calculation/engine.py _out_of_plane_geometry
A49: Statics
A50: Unknowns are the forces the supports exert on the body solved for: (Hx, Hz) of the heel on the boom, R_rb and R_fb of the leg bases on the legs, R_top of the top joint on the front leg (the rear leg gets -R_top). Moment equations are about the origin (M = x Fz - z Fx). The platform resultant is (r_g_x, r_g_z, m_g) = -(platform loads - the boom and leg reactions). | B50: calculation/solver/crane_solver.py _run_statics, _reactions_from_raw
...

Sheet Inputs
A1: Inputs -- the expanded crane model and the scene state
A2: Input (type here) | B2: Formula (do not edit) | C2: Generator marker | D2: Guard row (keep blank)
A4: Environment
A5: Gravity (signed, as authored) | B5: -9.81 | C5: m/s^2 | D5: gravity_m_s2 -- |g| is used
A6: Air density | B6: 1.225 | C6: kg/m^3 | D6: air_density_kg_m3
A7: Max wind speed (document) | B7: 15.1 | C7: m/s | D7: max_wind_speed_m_s -- information only; the scene wind speed is below
A8: Vessel motion reference x | B8: 0 | C8: m | D8: reference_x_m -- pitch/roll lever-arm origin
A9: Vessel motion reference z | B9: 0 | C9: m | D9: reference_z_m -- pitch/roll lever-arm origin
A11: Structure points and widths
A12: Boom width (heel left/right spacing) | B12: 19.1 | C12: m | D12: boom_width_m
A13: Slewing bearing diameter | B13: 23 | C13: m | D13: slewing_bearing_diameter_m -- optional; only bearing line loads use it
A14: Boom heel x | B14: 8.5 | C14: m | D14: boom_heel_x_m -- node boom_heel (also platform_heel)
A15: Boom heel z | B15: 8 | C15: m | D15: boom_heel_z_m -- node boom_heel (also platform_heel)
A16: Upper hinge x | B16: -11 | C16: m | D16: upper_hinge_x_m -- node rear_top (also front_top)
A17: Upper hinge z | B17: 52.3 | C17: m | D17: upper_hinge_z_m -- node rear_top (also front_top)
A18: Rear hinge x | B18: -11 | C18: m | D18: rear_hinge_x_m -- node rear_base (also platform_rear)
A19: Rear hinge z | B19: 7.7 | C19: m | D19: rear_hinge_z_m -- node rear_base (also platform_rear)
A20: Front hinge x | B20: 6.87 | C20: m | D20: front_hinge_x_m -- node front_base (also platform_front)
A21: Front hinge z | B21: 7.7 | C21: m | D21: front_hinge_z_m -- node front_base (also platform_front)
A22: Platform base x | B22: 0 | C22: m | D22: platform_base_x_m -- node platform_base
A23: Platform base z | B23: 0 | C23: m | D23: platform_base_z_m -- node platform_base
A25: Scene state (one operating point)
A26: Hook-loaded hoist id | B26: MH | D26: hoist_id -- a hoist with a fixed rope
A27: Boom angle | B27: 60 | C27: deg | D27: boom_angle_deg -- from +x toward +z
A28: Hook load (payload + hook block) x DAF x g | B28: 6500 | C28: kN | D28: hook_load_kN
A29: Tackle length (support sheave to hook) | B29: 40 | C29: m | D29: tackle_length_m
A30: Offlead | B30: 0 | C30: deg | D30: offlead_deg
A31: Sidelead | B31: 0 | C31: deg | D31: sidelead_deg
A32: Wind speed | B32: 0 | C32: m/s | D32: wind_speed_m_s
A33: Wind direction | B33: +X | D33: wind_direction
A34: Vessel acceleration ax | B34: 0 | C34: m/s^2 | D34: accel_x_m_s2
A35: Vessel acceleration ay | B35: 0 | C35: m/s^2 | D35: accel_y_m_s2
A36: Vessel acceleration az | B36: 0 | C36: m/s^2 | D36: accel_z_m_s2
A37: Pitch angular acceleration | B37: 0 | C37: rad/s^2 | D37: pitch_accel_rad_s2
A38: Roll angular acceleration | B38: 0 | C38: rad/s^2 | D38: roll_accel_rad_s2
A39: Vessel roll | B39: 0 | C39: deg | D39: vessel_roll_deg -- positive to starboard
A40: Vessel pitch | B40: 0 | C40: deg | D40: vessel_pitch_deg -- positive bow-down
A41: Crane slewing angle | B41: 0 | C41: deg | D41: crane_slewing_angle_deg
A43: Mass points (all bodies) | D43: Capacity | E43: 40 | F43: Rows not written (overflow) | G43: 0
A44: Active [1/0] | B44: Id | C44: Body | D44: Frame | E44: Mass [t] | F44: u (along boom) [m] | G44: v (lateral) [m] | H44: w (boom normal) [m] | I44: x [m] | J44: y [m] | K44: z [m]
...

Sheet Geometry
A1: Geometry -- node positions and crane-frame motion
A3: Crane (global) frame: x horizontal outboard, y lateral, z up; node positions are (x, z).
A4: Boom angle: degrees from +x toward +z, about the boom heel (node boom_heel). Boom-local (u, w): u along the boom, w normal (left of u). x = heel_x + u*cos(a) - w*sin(a); z = heel_z + u*sin(a) + w*cos(a).
A5: Hanging nodes sit directly below their parent node (same x, z lower by the drop). A missing drop counts as 1 m (the app's default). One level of hanging only (a hanging node whose parent is hanging trips the hanging_chain check).
A6: The active hook (the scene hoist's hook node) hangs the tackle length below its support node instead of its idle drop. Support node = the hook node's parent, else the hoist's support node. A negative tackle length counts as 0.
A7: Vessel frame: x forward, y port, z up. Pitch positive bow-down, roll positive to starboard; yaw drops out. Gravity in the vessel frame: (g sin p, -g sin r cos p, -g cos r cos p), g = |gravity|.
A8: Crane frame = vessel frame rotated about z by the slewing angle: a horizontal vessel vector (x, y) becomes (cos s x + sin s y, -sin s x + cos s y). z is unchanged.
A9: Load acceleration k = g - a (crane frame); the solver's equivalent reference acceleration is -k horizontally and -g - kz vertically (solver_ax/ay/az).
A12: Boom rotation and active hook
A13: Boom angle | B13: =RADIANS(Inputs!$B$27) | C13: rad | D13: boom_angle_rad
A14: cos(boom angle) | B14: =COS(Geometry!$B$13) | D14: boom_cos
A15: sin(boom angle) | B15: =SIN(Geometry!$B$13) | D15: boom_sin
A16: Row of node boom_heel in nodes | B16: =IFERROR(MATCH("boom_heel",Geometry!$B$58:$B$137,0),0) | C16: row | D16: heel_row -- 0 = missing
A17: Boom heel x | B17: =IF(Geometry!$B$16>0,INDEX(Inputs!$E$138:$E$217,Geometry!$B$16),0) | C17: m | D17: heel_x_m
A18: Boom heel z | B18: =IF(Geometry!$B$16>0,INDEX(Inputs!$F$138:$F$217,Geometry!$B$16),0) | C18: m | D18: heel_z_m
A19: Tackle length used | B19: =MAX(0,Inputs!$B$29) | C19: m | D19: tackle_m -- max(0, scene value)
A20: Active hook node id | B20: =IFERROR(INDEX(Inputs!$D$304:$D$311,MATCH(Inputs!$B$26,Inputs!$B$304:$B$311,0))&"","") | D20: hook_id
A21: Row of the hook node in nodes | B21: =IF(Geometry!$B$20="",0,IFERROR(MATCH(Geometry!$B$20,Geometry!$B$58:$B$137,0),0)) | C21: row | D21: hook_row -- 0 = missing
A22: Hook node's parent (below_node_id) | B22: =IF(Geometry!$B$21>0,INDEX(Inputs!$I$138:$I$217,Geometry!$B$21)&"","") | D22: hook_parent_id
A23: Hook support node id | B23: =IF(Geometry!$B$22<>"",Geometry!$B$22,IFERROR(INDEX(Inputs!$E$304:$E$311,MATCH(Inputs!$B$26,Inputs!$B$304:$B$311,0))&"","")) | D23: support_id
A24: Row of the support node in nodes | B24: =IF(Geometry!$B$23="",0,IFERROR(MATCH(Geometry!$B$23,Geometry!$B$58:$B$137,0),0)) | C24: row | D24: support_row -- 0 = missing
A25: Support node z (before the hook moves) | B25: =IF(Geometry!$B$24>0,INDEX(Geometry!$I$58:$I$137,Geometry!$B$24),0) | C25: m | D25: support_z_m
A26: Hook is lowered by the tackle | B26: =IF(AND(Geometry!$B$21>0,Geometry!$B$24>0),1,0) | C26: 1/0 | D26: hook_moves
A28: Vessel-frame motion in the crane frame
A29: Gravity magnitude |g| | B29: =ABS(Inputs!$B$5) | C29: m/s^2 | D29: g_m_s2
A30: Vessel roll | B30: =RADIANS(Inputs!$B$39) | C30: rad | D30: roll_rad
A31: Vessel pitch | B31: =RADIANS(Inputs!$B$40) | C31: rad | D31: pitch_rad
A32: Slewing angle | B32: =RADIANS(Inputs!$B$41) | C32: rad | D32: slew_rad
A33: cos(slew) | B33: =COS(Geometry!$B$32) | D33: slew_cos
A34: sin(slew) | B34: =SIN(Geometry!$B$32) | D34: slew_sin
A35: Gravity x, vessel frame | B35: =Geometry!$B$29*SIN(Geometry!$B$31) | C35: m/s^2 | D35: gx_vessel
A36: Gravity y, vessel frame | B36: =-Geometry!$B$29*SIN(Geometry!$B$30)*COS(Geometry!$B$31) | C36: m/s^2 | D36: gy_vessel
A37: Gravity z, vessel frame | B37: =-Geometry!$B$29*COS(Geometry!$B$30)*COS(Geometry!$B$31) | C37: m/s^2 | D37: gz_vessel
A38: k x = g - a, vessel frame | B38: =Geometry!$B$35-Inputs!$B$34 | C38: m/s^2 | D38: kx_vessel
A39: k y = g - a, vessel frame | B39: =Geometry!$B$36-Inputs!$B$35 | C39: m/s^2 | D39: ky_vessel
A40: Gravity x, crane frame | B40: =Geometry!$B$33*Geometry!$B$35+Geometry!$B$34*Geometry!$B$36 | C40: m/s^2 | D40: gx
A41: Gravity y, crane frame | B41: =-Geometry!$B$34*Geometry!$B$35+Geometry!$B$33*Geometry!$B$36 | C41: m/s^2 | D41: gy
A42: Gravity z, crane frame | B42: =Geometry!$B$37 | C42: m/s^2 | D42: gz
A43: Vessel acceleration x, crane frame | B43: =Geometry!$B$33*Inputs!$B$34+Geometry!$B$34*Inputs!$B$35 | C43: m/s^2 | D43: ax
A44: Vessel acceleration y, crane frame | B44: =-Geometry!$B$34*Inputs!$B$34+Geometry!$B$33*Inputs!$B$35 | C44: m/s^2 | D44: ay
...

Sheet Loads
A1: Loads -- in-plane loads on the four bodies
A3: In-plane (x, z) loads on the four bodies, row by row, as the solver accumulates them (calculation/solver/crane_solver.py _accumulate_loads). Moments are about the origin: M = x Fz - z Fx.
A4: Mass load = weight m g' (Gravity) + inertia -m (a' + lever x pitch') (Inertia); their sum is the solver's inertia_force with k = g - a. dx = x - x_ref, dz = z - z_ref.
A5: Rope self-weight is lumped at nodes (calculation/rope_mass.py rope_mass_at_nodes) and loaded like a mass point (gravity + inertia, column group 'rope weight').
A6: Rope tension: the scene hoist's rope carries hook load / parts at the hook; an idle hoist's rope m_hook (|g| + az') / parts (az' = solver_az on Geometry). The solve (boom hoist) rope has an unknown tension: its unit-tension coefficients bh_* are listed and Statics multiplies them by the solved tension.
A7: Parts at the hook = sum of the multipliers of the rope's active segments touching the hook node (min 1), as the solver does outside split mode; the hoists' Falls column is not used here (equal to those parts for 22689).
A8: Split-block mode is NOT supported: the hoists' splitable / split falls / split hook mass columns are ignored (the app's normal mode).
A9: Spare and inactive rows read 0; a zero-length segment carries no force.
A12: Scene values used by the loads
A13: Vessel motion reference x | B13: =Inputs!$B$8+0 | C13: m | D13: ref_x_m
A14: Vessel motion reference z | B14: =Inputs!$B$9+0 | C14: m | D14: ref_z_m
A15: Gravity x, crane frame (g') | B15: =Geometry!$B$40 | C15: m/s^2 | D15: gx -- Geometry
A16: Gravity z, crane frame (g') | B16: =Geometry!$B$42 | C16: m/s^2 | D16: gz -- Geometry
A17: Vessel acceleration x, crane frame (a') | B17: =Geometry!$B$43 | C17: m/s^2 | D17: ax -- Geometry
A18: Vessel acceleration z, crane frame (a') | B18: =Geometry!$B$45 | C18: m/s^2 | D18: az -- Geometry
A19: Pitch angular acceleration, crane frame | B19: =Geometry!$B$52 | C19: rad/s^2 | D19: pitch -- Geometry
A20: Idle rope acceleration |g| + solver_az | B20: =Geometry!$B$29+Geometry!$B$51 | C20: m/s^2 | D20: idle_accel
A21: In-plane wind sign | B21: =IF(Inputs!$B$32=0,0,IF(Inputs!$B$33="+X",1,IF(Inputs!$B$33="-X",-1,IF(OR(Inputs!$B$33="+Y",Inputs!$B$33="-Y"),0,1)))) | C21: +1/-1/0 | D21: wind_sign -- +X: 1, -X: -1, +Y/-Y: 0
A22: 0.5 rho V^2 / 1000 | B22: =0.5*Inputs!$B$6*Inputs!$B$32^2/1000 | C22: kN/m^2 | D22: wind_q_kN_m2
A23: |sin(boom angle)| (body boom areas) | B23: =ABS(Geometry!$B$15) | D23: boom_wind_scale
A24: Hook load | B24: =Inputs!$B$28+0 | C24: kN | D24: hook_kN -- scene value, as the solver uses it
A25: Offlead force sin(offlead) x hook load | B25: =SIN(RADIANS(Inputs!$B$30))*Loads!$B$24 | C25: kN | D25: offlead_fx_kN -- +x
A26: Row of the hook node in nodes | B26: =Geometry!$B$21 | C26: row | D26: hook_row -- 0 = missing
A27: Row of the offlead node (hook's parent, else the hook) | B27: =IF(Loads!$B$26=0,0,IF(Geometry!$B$22="",Loads!$B$26,IFERROR(MATCH(Geometry!$B$22,Geometry!$B$58:$B$137,0),Loads!$B$26))) | C27: row | D27: anchor_row -- 0 = missing
A28: Rope of the scene hoist | B28: =IFERROR(INDEX(Loads!$C$139:$C$146,MATCH(Inputs!$B$26,Loads!$B$139:$B$146,0))&"","") | D28: scene_rope_id
A30: Mass points (row i = Inputs mass points row i)
A31: Active [1/0] | B31: Body | C31: x global [m] | D31: z global [m] | E31: Mass [t] | F31: Weight Fx = m gx' [kN] | G31: Weight Fz = m gz' [kN] | H31: Weight moment [kNm] | I31: Inertia Fx = -m (ax' + pitch' dz) [kN] | J31: Inertia Fz = -m (az' - pitch' dx) [kN] | K31: Inertia moment [kNm] | L31: Fx total [kN] | M31: Fz total [kN] | N31: Moment total [kNm]
A32: active (from Inputs) | B32: body | C32: x_m (boom-local rotated about the heel) | D32: z_m | E32: mass_t | F32: grav_fx | G32: grav_fz | H32: grav_m | I32: inertia_fx | J32: inertia_fz | K32: inertia_m | L32: fx (crane_solver inertia_force) | M32: fz | N32: m
A33: =Inputs!$A$46 | B33: =IF(Loads!$A$33=1,Inputs!$C$46&"","") | C33: =IF(Loads!$A$33=1,IF(Inputs!$D$46="boom_local",Geometry!$B$17+Inputs!$F$46*Geometry!$B$14-Inputs!$H$46*Geometry!$B$15,Inputs!$I$46+0),0) | D33: =IF(Loads!$A$33=1,IF(Inputs!$D$46="boom_local",Geometry!$B$18+Inputs!$F$46*Geometry!$B$15+Inputs!$H$46*Geometry!$B$14,Inputs!$K$46+0),0) | E33: =IF(Loads!$A$33=1,Inputs!$E$46+0,0) | F33: =Loads!$E$33*Loads!$B$15 | G33: =Loads!$E$33*Loads!$B$16 | H33: =Loads!$C$33*Loads!$G$33-Loads!$D$33*Loads!$F$33 | I33: =-Loads!$E$33*(Loads!$B$17+Loads!$B$19*(Loads!$D$33-Loads!$B$14)) | J33: =-Loads!$E$33*(Loads!$B$18-Loads!$B$19*(Loads!$C$33-Loads!$B$13)) | K33: =Loads!$C$33*Loads!$J$33-Loads!$D$33*Loads!$I$33 | L33: =Loads!$F$33+Loads!$I$33 | M33: =Loads!$G$33+Loads!$J$33 | N33: =Loads!$H$33+Loads!$K$33
A34: =Inputs!$A$47 | B34: =IF(Loads!$A$34=1,Inputs!$C$47&"","") | C34: =IF(Loads!$A$34=1,IF(Inputs!$D$47="boom_local",Geometry!$B$17+Inputs!$F$47*Geometry!$B$14-Inputs!$H$47*Geometry!$B$15,Inputs!$I$47+0),0) | D34: =IF(Loads!$A$34=1,IF(Inputs!$D$47="boom_local",Geometry!$B$18+Inputs!$F$47*Geometry!$B$15+Inputs!$H$47*Geometry!$B$14,Inputs!$K$47+0),0) | E34: =IF(Loads!$A$34=1,Inputs!$E$47+0,0) | F34: =Loads!$E$34*Loads!$B$15 | G34: =Loads!$E$34*Loads!$B$16 | H34: =Loads!$C$34*Loads!$G$34-Loads!$D$34*Loads!$F$34 | I34: =-Loads!$E$34*(Loads!$B$17+Loads!$B$19*(Loads!$D$34-Loads!$B$14)) | J34: =-Loads!$E$34*(Loads!$B$18-Loads!$B$19*(Loads!$C$34-Loads!$B$13)) | K34: =Loads!$C$34*Loads!$J$34-Loads!$D$34*Loads!$I$34 | L34: =Loads!$F$34+Loads!$I$34 | M34: =Loads!$G$34+Loads!$J$34 | N34: =Loads!$H$34+Loads!$K$34
A35: =Inputs!$A$48 | B35: =IF(Loads!$A$35=1,Inputs!$C$48&"","") | C35: =IF(Loads!$A$35=1,IF(Inputs!$D$48="boom_local",Geometry!$B$17+Inputs!$F$48*Geometry!$B$14-Inputs!$H$48*Geometry!$B$15,Inputs!$I$48+0),0) | D35: =IF(Loads!$A$35=1,IF(Inputs!$D$48="boom_local",Geometry!$B$18+Inputs!$F$48*Geometry!$B$15+Inputs!$H$48*Geometry!$B$14,Inputs!$K$48+0),0) | E35: =IF(Loads!$A$35=1,Inputs!$E$48+0,0) | F35: =Loads!$E$35*Loads!$B$15 | G35: =Loads!$E$35*Loads!$B$16 | H35: =Loads!$C$35*Loads!$G$35-Loads!$D$35*Loads!$F$35 | I35: =-Loads!$E$35*(Loads!$B$17+Loads!$B$19*(Loads!$D$35-Loads!$B$14)) | J35: =-Loads!$E$35*(Loads!$B$18-Loads!$B$19*(Loads!$C$35-Loads!$B$13)) | K35: =Loads!$C$35*Loads!$J$35-Loads!$D$35*Loads!$I$35 | L35: =Loads!$F$35+Loads!$I$35 | M35: =Loads!$G$35+Loads!$J$35 | N35: =Loads!$H$35+Loads!$K$35
A36: =Inputs!$A$49 | B36: =IF(Loads!$A$36=1,Inputs!$C$49&"","") | C36: =IF(Loads!$A$36=1,IF(Inputs!$D$49="boom_local",Geometry!$B$17+Inputs!$F$49*Geometry!$B$14-Inputs!$H$49*Geometry!$B$15,Inputs!$I$49+0),0) | D36: =IF(Loads!$A$36=1,IF(Inputs!$D$49="boom_local",Geometry!$B$18+Inputs!$F$49*Geometry!$B$15+Inputs!$H$49*Geometry!$B$14,Inputs!$K$49+0),0) | E36: =IF(Loads!$A$36=1,Inputs!$E$49+0,0) | F36: =Loads!$E$36*Loads!$B$15 | G36: =Loads!$E$36*Loads!$B$16 | H36: =Loads!$C$36*Loads!$G$36-Loads!$D$36*Loads!$F$36 | I36: =-Loads!$E$36*(Loads!$B$17+Loads!$B$19*(Loads!$D$36-Loads!$B$14)) | J36: =-Loads!$E$36*(Loads!$B$18-Loads!$B$19*(Loads!$C$36-Loads!$B$13)) | K36: =Loads!$C$36*Loads!$J$36-Loads!$D$36*Loads!$I$36 | L36: =Loads!$F$36+Loads!$I$36 | M36: =Loads!$G$36+Loads!$J$36 | N36: =Loads!$H$36+Loads!$K$36
A37: =Inputs!$A$50 | B37: =IF(Loads!$A$37=1,Inputs!$C$50&"","") | C37: =IF(Loads!$A$37=1,IF(Inputs!$D$50="boom_local",Geometry!$B$17+Inputs!$F$50*Geometry!$B$14-Inputs!$H$50*Geometry!$B$15,Inputs!$I$50+0),0) | D37: =IF(Loads!$A$37=1,IF(Inputs!$D$50="boom_local",Geometry!$B$18+Inputs!$F$50*Geometry!$B$15+Inputs!$H$50*Geometry!$B$14,Inputs!$K$50+0),0) | E37: =IF(Loads!$A$37=1,Inputs!$E$50+0,0) | F37: =Loads!$E$37*Loads!$B$15 | G37: =Loads!$E$37*Loads!$B$16 | H37: =Loads!$C$37*Loads!$G$37-Loads!$D$37*Loads!$F$37 | I37: =-Loads!$E$37*(Loads!$B$17+Loads!$B$19*(Loads!$D$37-Loads!$B$14)) | J37: =-Loads!$E$37*(Loads!$B$18-Loads!$B$19*(Loads!$C$37-Loads!$B$13)) | K37: =Loads!$C$37*Loads!$J$37-Loads!$D$37*Loads!$I$37 | L37: =Loads!$F$37+Loads!$I$37 | M37: =Loads!$G$37+Loads!$J$37 | N37: =Loads!$H$37+Loads!$K$37
A38: =Inputs!$A$51 | B38: =IF(Loads!$A$38=1,Inputs!$C$51&"","") | C38: =IF(Loads!$A$38=1,IF(Inputs!$D$51="boom_local",Geometry!$B$17+Inputs!$F$51*Geometry!$B$14-Inputs!$H$51*Geometry!$B$15,Inputs!$I$51+0),0) | D38: =IF(Loads!$A$38=1,IF(Inputs!$D$51="boom_local",Geometry!$B$18+Inputs!$F$51*Geometry!$B$15+Inputs!$H$51*Geometry!$B$14,Inputs!$K$51+0),0) | E38: =IF(Loads!$A$38=1,Inputs!$E$51+0,0) | F38: =Loads!$E$38*Loads!$B$15 | G38: =Loads!$E$38*Loads!$B$16 | H38: =Loads!$C$38*Loads!$G$38-Loads!$D$38*Loads!$F$38 | I38: =-Loads!$E$38*(Loads!$B$17+Loads!$B$19*(Loads!$D$38-Loads!$B$14)) | J38: =-Loads!$E$38*(Loads!$B$18-Loads!$B$19*(Loads!$C$38-Loads!$B$13)) | K38: =Loads!$C$38*Loads!$J$38-Loads!$D$38*Loads!$I$38 | L38: =Loads!$F$38+Loads!$I$38 | M38: =Loads!$G$38+Loads!$J$38 | N38: =Loads!$H$38+Loads!$K$38
A39: =Inputs!$A$52 | B39: =IF(Loads!$A$39=1,Inputs!$C$52&"","") | C39: =IF(Loads!$A$39=1,IF(Inputs!$D$52="boom_local",Geometry!$B$17+Inputs!$F$52*Geometry!$B$14-Inputs!$H$52*Geometry!$B$15,Inputs!$I$52+0),0) | D39: =IF(Loads!$A$39=1,IF(Inputs!$D$52="boom_local",Geometry!$B$18+Inputs!$F$52*Geometry!$B$15+Inputs!$H$52*Geometry!$B$14,Inputs!$K$52+0),0) | E39: =IF(Loads!$A$39=1,Inputs!$E$52+0,0) | F39: =Loads!$E$39*Loads!$B$15 | G39: =Loads!$E$39*Loads!$B$16 | H39: =Loads!$C$39*Loads!$G$39-Loads!$D$39*Loads!$F$39 | I39: =-Loads!$E$39*(Loads!$B$17+Loads!$B$19*(Loads!$D$39-Loads!$B$14)) | J39: =-Loads!$E$39*(Loads!$B$18-Loads!$B$19*(Loads!$C$39-Loads!$B$13)) | K39: =Loads!$C$39*Loads!$J$39-Loads!$D$39*Loads!$I$39 | L39: =Loads!$F$39+Loads!$I$39 | M39: =Loads!$G$39+Loads!$J$39 | N39: =Loads!$H$39+Loads!$K$39
A40: =Inputs!$A$53 | B40: =IF(Loads!$A$40=1,Inputs!$C$53&"","") | C40: =IF(Loads!$A$40=1,IF(Inputs!$D$53="boom_local",Geometry!$B$17+Inputs!$F$53*Geometry!$B$14-Inputs!$H$53*Geometry!$B$15,Inputs!$I$53+0),0) | D40: =IF(Loads!$A$40=1,IF(Inputs!$D$53="boom_local",Geometry!$B$18+Inputs!$F$53*Geometry!$B$15+Inputs!$H$53*Geometry!$B$14,Inputs!$K$53+0),0) | E40: =IF(Loads!$A$40=1,Inputs!$E$53+0,0) | F40: =Loads!$E$40*Loads!$B$15 | G40: =Loads!$E$40*Loads!$B$16 | H40: =Loads!$C$40*Loads!$G$40-Loads!$D$40*Loads!$F$40 | I40: =-Loads!$E$40*(Loads!$B$17+Loads!$B$19*(Loads!$D$40-Loads!$B$14)) | J40: =-Loads!$E$40*(Loads!$B$18-Loads!$B$19*(Loads!$C$40-Loads!$B$13)) | K40: =Loads!$C$40*Loads!$J$40-Loads!$D$40*Loads!$I$40 | L40: =Loads!$F$40+Loads!$I$40 | M40: =Loads!$G$40+Loads!$J$40 | N40: =Loads!$H$40+Loads!$K$40
A41: =Inputs!$A$54 | B41: =IF(Loads!$A$41=1,Inputs!$C$54&"","") | C41: =IF(Loads!$A$41=1,IF(Inputs!$D$54="boom_local",Geometry!$B$17+Inputs!$F$54*Geometry!$B$14-Inputs!$H$54*Geometry!$B$15,Inputs!$I$54+0),0) | D41: =IF(Loads!$A$41=1,IF(Inputs!$D$54="boom_local",Geometry!$B$18+Inputs!$F$54*Geometry!$B$15+Inputs!$H$54*Geometry!$B$14,Inputs!$K$54+0),0) | E41: =IF(Loads!$A$41=1,Inputs!$E$54+0,0) | F41: =Loads!$E$41*Loads!$B$15 | G41: =Loads!$E$41*Loads!$B$16 | H41: =Loads!$C$41*Loads!$G$41-Loads!$D$41*Loads!$F$41 | I41: =-Loads!$E$41*(Loads!$B$17+Loads!$B$19*(Loads!$D$41-Loads!$B$14)) | J41: =-Loads!$E$41*(Loads!$B$18-Loads!$B$19*(Loads!$C$41-Loads!$B$13)) | K41: =Loads!$C$41*Loads!$J$41-Loads!$D$41*Loads!$I$41 | L41: =Loads!$F$41+Loads!$I$41 | M41: =Loads!$G$41+Loads!$J$41 | N41: =Loads!$H$41+Loads!$K$41
A42: =Inputs!$A$55 | B42: =IF(Loads!$A$42=1,Inputs!$C$55&"","") | C42: =IF(Loads!$A$42=1,IF(Inputs!$D$55="boom_local",Geometry!$B$17+Inputs!$F$55*Geometry!$B$14-Inputs!$H$55*Geometry!$B$15,Inputs!$I$55+0),0) | D42: =IF(Loads!$A$42=1,IF(Inputs!$D$55="boom_local",Geometry!$B$18+Inputs!$F$55*Geometry!$B$15+Inputs!$H$55*Geometry!$B$14,Inputs!$K$55+0),0) | E42: =IF(Loads!$A$42=1,Inputs!$E$55+0,0) | F42: =Loads!$E$42*Loads!$B$15 | G42: =Loads!$E$42*Loads!$B$16 | H42: =Loads!$C$42*Loads!$G$42-Loads!$D$42*Loads!$F$42 | I42: =-Loads!$E$42*(Loads!$B$17+Loads!$B$19*(Loads!$D$42-Loads!$B$14)) | J42: =-Loads!$E$42*(Loads!$B$18-Loads!$B$19*(Loads!$C$42-Loads!$B$13)) | K42: =Loads!$C$42*Loads!$J$42-Loads!$D$42*Loads!$I$42 | L42: =Loads!$F$42+Loads!$I$42 | M42: =Loads!$G$42+Loads!$J$42 | N42: =Loads!$H$42+Loads!$K$42
A43: =Inputs!$A$56 | B43: =IF(Loads!$A$43=1,Inputs!$C$56&"","") | C43: =IF(Loads!$A$43=1,IF(Inputs!$D$56="boom_local",Geometry!$B$17+Inputs!$F$56*Geometry!$B$14-Inputs!$H$56*Geometry!$B$15,Inputs!$I$56+0),0) | D43: =IF(Loads!$A$43=1,IF(Inputs!$D$56="boom_local",Geometry!$B$18+Inputs!$F$56*Geometry!$B$15+Inputs!$H$56*Geometry!$B$14,Inputs!$K$56+0),0) | E43: =IF(Loads!$A$43=1,Inputs!$E$56+0,0) | F43: =Loads!$E$43*Loads!$B$15 | G43: =Loads!$E$43*Loads!$B$16 | H43: =Loads!$C$43*Loads!$G$43-Loads!$D$43*Loads!$F$43 | I43: =-Loads!$E$43*(Loads!$B$17+Loads!$B$19*(Loads!$D$43-Loads!$B$14)) | J43: =-Loads!$E$43*(Loads!$B$18-Loads!$B$19*(Loads!$C$43-Loads!$B$13)) | K43: =Loads!$C$43*Loads!$J$43-Loads!$D$43*Loads!$I$43 | L43: =Loads!$F$43+Loads!$I$43 | M43: =Loads!$G$43+Loads!$J$43 | N43: =Loads!$H$43+Loads!$K$43
A44: =Inputs!$A$57 | B44: =IF(Loads!$A$44=1,Inputs!$C$57&"","") | C44: =IF(Loads!$A$44=1,IF(Inputs!$D$57="boom_local",Geometry!$B$17+Inputs!$F$57*Geometry!$B$14-Inputs!$H$57*Geometry!$B$15,Inputs!$I$57+0),0) | D44: =IF(Loads!$A$44=1,IF(Inputs!$D$57="boom_local",Geometry!$B$18+Inputs!$F$57*Geometry!$B$15+Inputs!$H$57*Geometry!$B$14,Inputs!$K$57+0),0) | E44: =IF(Loads!$A$44=1,Inputs!$E$57+0,0) | F44: =Loads!$E$44*Loads!$B$15 | G44: =Loads!$E$44*Loads!$B$16 | H44: =Loads!$C$44*Loads!$G$44-Loads!$D$44*Loads!$F$44 | I44: =-Loads!$E$44*(Loads!$B$17+Loads!$B$19*(Loads!$D$44-Loads!$B$14)) | J44: =-Loads!$E$44*(Loads!$B$18-Loads!$B$19*(Loads!$C$44-Loads!$B$13)) | K44: =Loads!$C$44*Loads!$J$44-Loads!$D$44*Loads!$I$44 | L44: =Loads!$F$44+Loads!$I$44 | M44: =Loads!$G$44+Loads!$J$44 | N44: =Loads!$H$44+Loads!$K$44
...

Sheet Statics
A1: Statics -- boom and leg-frame equilibrium solves
A3: The app's in-plane statics, solved once with the actual loads (calculation/solver/crane_solver.py _run_statics): boom 3x3, then the leg frame 6x6, then the platform resultant. Moments are about the origin (M = x Fz - z Fx).
A4: Body loads = known loads (Loads body totals fx/fz/m) + T_bh x solve-rope coefficients (bh_fx/bh_fz/bh_m). Unknowns are the forces the supports exert on the body solved for (heel and leg-base reactions: weight gives positive Fz).
A5: Each system A x = b is solved with MMULT(MINVERSE(A), b) (a legacy array formula). The app calls np.linalg.solve and gives no result when it raises (an exactly singular matrix). Here a matrix is flagged singular when |det A| <= 1e-12 x the product of its row norms (Hadamard bound), or when MINVERSE fails; the solution column then reads 0 and Results shows a message.
A6: With no active solve rope the boom matrix's third column is all zero: the app shows no results (compute_analysis_point returns None); Results says so.
A9: Status
A10: Active solve ropes | B10: =COUNTIFS(Inputs!$A$290:$A$297,1,Inputs!$C$290:$C$297,"solve") | C10: count | D10: solve_ropes -- the app needs one
A11: Boom 3x3 singular | B11: =Statics!$B$41 | C11: 1/0 | D11: boom_singular
A12: Leg frame 6x6 singular | B12: =Statics!$B$62 | C12: 1/0 | D12: leg_singular
A13: Statics solved | B13: =IF(AND(Statics!$B$10>0,Statics!$B$11=0,Statics!$B$12=0),1,0) | C13: 1/0 | D13: ok -- a solve rope and no singular matrix
A15: Structure node positions
A16: Node boom_heel x | B16: =IFERROR(INDEX(Geometry!$K$58:$K$137,MATCH("boom_heel",Geometry!$B$58:$B$137,0)),0) | C16: m | D16: boom_heel_x_m -- Geometry x_m/z_m; 0 if missing
A17: Node boom_heel z | B17: =IFERROR(INDEX(Geometry!$L$58:$L$137,MATCH("boom_heel",Geometry!$B$58:$B$137,0)),0) | C17: m | D17: boom_heel_z_m -- Geometry x_m/z_m; 0 if missing
A18: Node rear_base x | B18: =IFERROR(INDEX(Geometry!$K$58:$K$137,MATCH("rear_base",Geometry!$B$58:$B$137,0)),0) | C18: m | D18: rear_base_x_m -- Geometry x_m/z_m; 0 if missing
A19: Node rear_base z | B19: =IFERROR(INDEX(Geometry!$L$58:$L$137,MATCH("rear_base",Geometry!$B$58:$B$137,0)),0) | C19: m | D19: rear_base_z_m -- Geometry x_m/z_m; 0 if missing
A20: Node rear_top x | B20: =IFERROR(INDEX(Geometry!$K$58:$K$137,MATCH("rear_top",Geometry!$B$58:$B$137,0)),0) | C20: m | D20: rear_top_x_m -- Geometry x_m/z_m; 0 if missing
A21: Node rear_top z | B21: =IFERROR(INDEX(Geometry!$L$58:$L$137,MATCH("rear_top",Geometry!$B$58:$B$137,0)),0) | C21: m | D21: rear_top_z_m -- Geometry x_m/z_m; 0 if missing
A22: Node front_base x | B22: =IFERROR(INDEX(Geometry!$K$58:$K$137,MATCH("front_base",Geometry!$B$58:$B$137,0)),0) | C22: m | D22: front_base_x_m -- Geometry x_m/z_m; 0 if missing
A23: Node front_base z | B23: =IFERROR(INDEX(Geometry!$L$58:$L$137,MATCH("front_base",Geometry!$B$58:$B$137,0)),0) | C23: m | D23: front_base_z_m -- Geometry x_m/z_m; 0 if missing
A24: Node front_top x | B24: =IFERROR(INDEX(Geometry!$K$58:$K$137,MATCH("front_top",Geometry!$B$58:$B$137,0)),0) | C24: m | D24: front_top_x_m -- Geometry x_m/z_m; 0 if missing
A25: Node front_top z | B25: =IFERROR(INDEX(Geometry!$L$58:$L$137,MATCH("front_top",Geometry!$B$58:$B$137,0)),0) | C25: m | D25: front_top_z_m -- Geometry x_m/z_m; 0 if missing
A26: Node platform_heel x | B26: =IFERROR(INDEX(Geometry!$K$58:$K$137,MATCH("platform_heel",Geometry!$B$58:$B$137,0)),0) | C26: m | D26: platform_heel_x_m -- Geometry x_m/z_m; 0 if missing
A27: Node platform_heel z | B27: =IFERROR(INDEX(Geometry!$L$58:$L$137,MATCH("platform_heel",Geometry!$B$58:$B$137,0)),0) | C27: m | D27: platform_heel_z_m -- Geometry x_m/z_m; 0 if missing
A28: Node platform_rear x | B28: =IFERROR(INDEX(Geometry!$K$58:$K$137,MATCH("platform_rear",Geometry!$B$58:$B$137,0)),0) | C28: m | D28: platform_rear_x_m -- Geometry x_m/z_m; 0 if missing
A29: Node platform_rear z | B29: =IFERROR(INDEX(Geometry!$L$58:$L$137,MATCH("platform_rear",Geometry!$B$58:$B$137,0)),0) | C29: m | D29: platform_rear_z_m -- Geometry x_m/z_m; 0 if missing
A30: Node platform_front x | B30: =IFERROR(INDEX(Geometry!$K$58:$K$137,MATCH("platform_front",Geometry!$B$58:$B$137,0)),0) | C30: m | D30: platform_front_x_m -- Geometry x_m/z_m; 0 if missing
A31: Node platform_front z | B31: =IFERROR(INDEX(Geometry!$L$58:$L$137,MATCH("platform_front",Geometry!$B$58:$B$137,0)),0) | C31: m | D31: platform_front_z_m -- Geometry x_m/z_m; 0 if missing
A33: Boom: [Hx, Hz, T_bh] -- A x = b
A34: Equation | B34: A: coefficient of h_x | C34: A: coefficient of h_z | D34: A: coefficient of t_bh | E34: b (right-hand side) [kN or kNm] | F34: Unknown x | G34: MMULT(MINVERSE(A), b) | H34: x used (0 if singular) | I34: Row norm |A_i|
A35: Boom: sum Fx = 0 | B35: 1 | C35: 0 | D35: =Loads!$Z$305 | E35: =-Loads!$W$305 | F35: h_x: Hx: heel on boom [kN] | G35: {=MMULT(MINVERSE($B$35:$D$37),$E$35:$E$37)} | H35: =IF(Statics!$B$41=1,0,Statics!$G$35) | I35: =SQRT(SUMSQ(B35:D35))
A36: Boom: sum Fz = 0 | B36: 0 | C36: 1 | D36: =Loads!$AA$305 | E36: =-Loads!$X$305 | F36: h_z: Hz: heel on boom [kN] | H36: =IF(Statics!$B$41=1,0,Statics!$G$36) | I36: =SQRT(SUMSQ(B36:D36))
A37: Boom: sum M about the origin = 0 | B37: =-Statics!$B$17 | C37: =Statics!$B$16 | D37: =Loads!$AB$305 | E37: =-Loads!$Y$305 | F37: t_bh: T_bh: solve-rope tension [kN] | H37: =IF(Statics!$B$41=1,0,Statics!$G$37) | I37: =SQRT(SUMSQ(B37:D37))
A38: det A (MDETERM) | B38: =MDETERM($B$35:$D$37) | D38: det
A39: Product of the row norms of A | B39: =PRODUCT($I$35:$I$37) | D39: norm_product
A40: |det A| / product of row norms | B40: =IF(Statics!$B$39>0,ABS(Statics!$B$38)/Statics!$B$39,0) | D40: rel_det -- 1 = orthogonal rows, 0 = singular
A41: Singular | B41: =IF(OR(Statics!$B$40<=1E-12,ISERROR(SUM($G$35:$G$37))),1,0) | C41: 1/0 | D41: singular -- rel_det <= 1e-12 or MINVERSE fails
A43: Leg loads with the solved T_bh
A44: Rear leg load FX = ld + T_bh bh | B44: =Loads!$W$306+Statics!$H$37*Loads!$Z$306 | C44: kN | D44: rear_fx
A45: Rear leg load FZ = ld + T_bh bh | B45: =Loads!$X$306+Statics!$H$37*Loads!$AA$306 | C45: kN | D45: rear_fz
A46: Rear leg load M = ld + T_bh bh | B46: =Loads!$Y$306+Statics!$H$37*Loads!$AB$306 | C46: kNm | D46: rear_m
...

Sheet OutOfPlane
A1: OutOfPlane -- Y loads, left/right split, platform Fy and Mx
A3: The app's out-of-plane (Y) pass (calculation/engine.py _out_of_plane_variants, _out_of_plane_geometry, _augment_point_with_out_of_plane_loads), evaluated once with the actual hook load. It does not change the in-plane solve; it adds the left/right support split and the platform base Fy and Mx.
A4: Y loads: every mass point and every lumped mass (rope self-weight, idle hook blocks; y = 0) carries Fy = -m (ay' - roll' (z - z_ref)) (crane-frame ay' = Geometry solver_ay, roll' = roll_accel_crane); Y wind Fy = sign q Cd A_y scale (scale = |sin(boom angle)| for boom-local areas only); the sidelead force sin(sidelead) x hook load acts in +y at the scene hoist's support node (its hook node if the support is missing), at its kinematic position (before the tackle moves the hook).
A5: Moments of the applied loads about each support group origin (heel = boom_heel, front_leg = front_base, rear_leg = rear_base, platform_base = platform_heel): Mx = y Fz - (z - oz) Fy, Mz = (x - ox) Fy - y Fx. Mass Fx/Fz are the Loads mass loads (weight + inertia); wind and side forces have y = 0.
A6: Split (as the app, possibly an app sign bug): left = 0.5 total + M / boom width, right = 0.5 total - M / boom width, Fx using Mz and Fz using Mx; total = the in-plane reaction (Statics). So heel_left behaves as the -Y side.
A7: Platform base Fy = the sum of all applied Fy, Mx = Mx of the applied loads about platform_heel: the sign of the loads, not of a reaction (as the app). The front/rear leg splits are shown but the Scene does not report them.
A8: Boom width must be > 0: the app rejects 0 and its split divides by it; Results then shows a message (check zero_boom_width).
A11: Scene values used by the out-of-plane pass
A12: Vessel motion reference z (roll lever origin) | B12: =Loads!$B$14 | C12: m | D12: ref_z_m -- Loads
A13: Crane-frame Y acceleration ay' (= -ky) | B13: =Geometry!$B$50 | C13: m/s^2 | D13: ay -- Geometry solver_ay
A14: Roll angular acceleration, crane frame | B14: =Geometry!$B$53 | C14: rad/s^2 | D14: roll -- Geometry
A15: Y wind sign | B15: =IF(Inputs!$B$32=0,0,IF(Inputs!$B$33="+Y",1,IF(Inputs!$B$33="-Y",-1,0))) | C15: +1/-1/0 | D15: wind_y_sign -- +Y: 1, -Y: -1, X wind or speed 0: 0
A16: 0.5 rho V^2 / 1000 | B16: =Loads!$B$22 | C16: kN/m^2 | D16: wind_q_kN_m2 -- Loads
A17: |sin(boom angle)| (boom-local areas) | B17: =Loads!$B$23 | D17: boom_wind_scale -- Loads
A18: Hook load | B18: =Loads!$B$24 | C18: kN | D18: hook_kN -- scene value
A19: Side force sin(sidelead) x hook load | B19: =SIN(RADIANS(Inputs!$B$31))*OutOfPlane!$B$18 | C19: kN | D19: sidelead_kN -- +y
A20: Boom width (heel left/right spacing) | B20: =Inputs!$B$12+0 | C20: m | D20: boom_width_m -- Inputs structure
A21: Boom width > 0 | B21: =IF(OutOfPlane!$B$20>0,1,0) | C21: 1/0 | D21: width_ok -- 0 trips check zero_boom_width
A22: Slewing bearing diameter | B22: =Inputs!$B$13+0 | C22: m | D22: bearing_d_m -- Inputs structure; may be blank
A23: Bearing diameter > 0 | B23: =IF(OutOfPlane!$B$22>0,1,0) | C23: 1/0 | D23: bearing_ok -- 0: bearing rows are n/a
A25: Sidelead force (scene hoist)
A26: Row of the scene hoist in hoists | B26: =IF(Inputs!$B$26="",0,IFERROR(MATCH(Inputs!$B$26,Loads!$B$139:$B$146,0),0)) | C26: row | D26: hoist_row -- 0 = missing
A27: Its support node | B27: =IF(OutOfPlane!$B$26>0,INDEX(Inputs!$E$304:$E$311,OutOfPlane!$B$26)&"","") | D27: support_id -- Inputs hoists support_node_id
A28: Its hook node (fallback) | B28: =IF(OutOfPlane!$B$26>0,INDEX(Inputs!$D$304:$D$311,OutOfPlane!$B$26)&"","") | D28: hook_id -- Inputs hoists load_node_id
A29: Row of the support node in nodes | B29: =IF(OutOfPlane!$B$27="",0,IFERROR(MATCH(OutOfPlane!$B$27,Geometry!$B$58:$B$137,0),0)) | C29: row | D29: support_row -- 0 = missing
A30: Row of the hook node in nodes | B30: =IF(OutOfPlane!$B$28="",0,IFERROR(MATCH(OutOfPlane!$B$28,Geometry!$B$58:$B$137,0),0)) | C30: row | D30: hook_row -- 0 = missing
A31: Row of the node the side force acts at | B31: =IF(OutOfPlane!$B$29>0,OutOfPlane!$B$29,OutOfPlane!$B$30) | C31: row | D31: node_row -- support, else hook
A32: Its x (kinematics) | B32: =IF(OutOfPlane!$B$31>0,INDEX(Geometry!$H$58:$H$137,OutOfPlane!$B$31),0) | C32: m | D32: x_m -- Geometry x_kin_m
A33: Its z (kinematics) | B33: =IF(OutOfPlane!$B$31>0,INDEX(Geometry!$I$58:$I$137,OutOfPlane!$B$31),0) | C33: m | D33: z_m -- Geometry z_kin_m
A34: Side force Fy | B34: =IF(OutOfPlane!$B$31>0,OutOfPlane!$B$19,0) | C34: kN | D34: fy_kN -- 0 if no node
A36: Mass points (row i = Inputs mass points row i)
A37: Active [1/0] | B37: Body | C37: Frame | D37: x global [m] | E37: y (boom-local v, else y) [m] | F37: z global [m] | G37: Mass [t] | H37: Fx = weight + inertia [kN] | I37: Fz = weight + inertia [kN] | J37: Fy = -m (ay' - roll' (z - z_ref)) [kN]
A38: active (from Inputs) | B38: body | C38: frame | D38: x_m (Loads) | E38: y_m | F38: z_m (Loads) | G38: mass_t | H38: fx_kN (Loads) | I38: fz_kN (Loads) | J38: fy_kN
A39: =Inputs!$A$46 | B39: =Loads!$B$33 | C39: =IF(OutOfPlane!$A$39=1,Inputs!$D$46&"","") | D39: =Loads!$C$33 | E39: =IF(OutOfPlane!$A$39=1,IF(OutOfPlane!$C$39="boom_local",Inputs!$G$46,Inputs!$J$46)+0,0) | F39: =Loads!$D$33 | G39: =Loads!$E$33 | H39: =Loads!$L$33 | I39: =Loads!$M$33 | J39: =-OutOfPlane!$G$39*(OutOfPlane!$B$13-OutOfPlane!$B$14*(OutOfPlane!$F$39-OutOfPlane!$B$12))
A40: =Inputs!$A$47 | B40: =Loads!$B$34 | C40: =IF(OutOfPlane!$A$40=1,Inputs!$D$47&"","") | D40: =Loads!$C$34 | E40: =IF(OutOfPlane!$A$40=1,IF(OutOfPlane!$C$40="boom_local",Inputs!$G$47,Inputs!$J$47)+0,0) | F40: =Loads!$D$34 | G40: =Loads!$E$34 | H40: =Loads!$L$34 | I40: =Loads!$M$34 | J40: =-OutOfPlane!$G$40*(OutOfPlane!$B$13-OutOfPlane!$B$14*(OutOfPlane!$F$40-OutOfPlane!$B$12))
A41: =Inputs!$A$48 | B41: =Loads!$B$35 | C41: =IF(OutOfPlane!$A$41=1,Inputs!$D$48&"","") | D41: =Loads!$C$35 | E41: =IF(OutOfPlane!$A$41=1,IF(OutOfPlane!$C$41="boom_local",Inputs!$G$48,Inputs!$J$48)+0,0) | F41: =Loads!$D$35 | G41: =Loads!$E$35 | H41: =Loads!$L$35 | I41: =Loads!$M$35 | J41: =-OutOfPlane!$G$41*(OutOfPlane!$B$13-OutOfPlane!$B$14*(OutOfPlane!$F$41-OutOfPlane!$B$12))
A42: =Inputs!$A$49 | B42: =Loads!$B$36 | C42: =IF(OutOfPlane!$A$42=1,Inputs!$D$49&"","") | D42: =Loads!$C$36 | E42: =IF(OutOfPlane!$A$42=1,IF(OutOfPlane!$C$42="boom_local",Inputs!$G$49,Inputs!$J$49)+0,0) | F42: =Loads!$D$36 | G42: =Loads!$E$36 | H42: =Loads!$L$36 | I42: =Loads!$M$36 | J42: =-OutOfPlane!$G$42*(OutOfPlane!$B$13-OutOfPlane!$B$14*(OutOfPlane!$F$42-OutOfPlane!$B$12))
A43: =Inputs!$A$50 | B43: =Loads!$B$37 | C43: =IF(OutOfPlane!$A$43=1,Inputs!$D$50&"","") | D43: =Loads!$C$37 | E43: =IF(OutOfPlane!$A$43=1,IF(OutOfPlane!$C$43="boom_local",Inputs!$G$50,Inputs!$J$50)+0,0) | F43: =Loads!$D$37 | G43: =Loads!$E$37 | H43: =Loads!$L$37 | I43: =Loads!$M$37 | J43: =-OutOfPlane!$G$43*(OutOfPlane!$B$13-OutOfPlane!$B$14*(OutOfPlane!$F$43-OutOfPlane!$B$12))
A44: =Inputs!$A$51 | B44: =Loads!$B$38 | C44: =IF(OutOfPlane!$A$44=1,Inputs!$D$51&"","") | D44: =Loads!$C$38 | E44: =IF(OutOfPlane!$A$44=1,IF(OutOfPlane!$C$44="boom_local",Inputs!$G$51,Inputs!$J$51)+0,0) | F44: =Loads!$D$38 | G44: =Loads!$E$38 | H44: =Loads!$L$38 | I44: =Loads!$M$38 | J44: =-OutOfPlane!$G$44*(OutOfPlane!$B$13-OutOfPlane!$B$14*(OutOfPlane!$F$44-OutOfPlane!$B$12))
A45: =Inputs!$A$52 | B45: =Loads!$B$39 | C45: =IF(OutOfPlane!$A$45=1,Inputs!$D$52&"","") | D45: =Loads!$C$39 | E45: =IF(OutOfPlane!$A$45=1,IF(OutOfPlane!$C$45="boom_local",Inputs!$G$52,Inputs!$J$52)+0,0) | F45: =Loads!$D$39 | G45: =Loads!$E$39 | H45: =Loads!$L$39 | I45: =Loads!$M$39 | J45: =-OutOfPlane!$G$45*(OutOfPlane!$B$13-OutOfPlane!$B$14*(OutOfPlane!$F$45-OutOfPlane!$B$12))
...

Sheet Results
A1: Results -- rope tensions and support reactions
A3: What the Scene results table shows (core/analysis_services.py compute_result_rows), for the operating state on Inputs. Units: kN, kNm.
A4: Rope tensions: the solve rope's hoist reads T_bh (Statics); fixed ropes read their Loads tension (scene hoist: hook load / parts; idle hoists: hook mass x (|g| + az') / parts).
A5: Reactions (calculation/solver/crane_solver.py _reactions_from_raw): heel_point = (Hx, Hz), rear_hinge = R_rb, front_hinge = R_fb, upper_hinge = R_top, platform_base = (r_g_x, r_g_z, m_g). Support reactions: weight gives positive Fz. Pinned supports carry no moment.
A6: resultant = sqrt(Fx^2 + Fz^2); leg_axial = Fx ux + Fz uz and leg_normal = -Fx uz + Fz ux along base -> top (core/demand_extraction.py, calculation/engine.py resolve_connection_component_linear_response).
A7: When Statics has no solution (no solve rope, or a singular matrix) or the boom width is not > 0, every value cell shows the reason instead of a number, as the app shows no results.
A8: Out-of-plane rows (OutOfPlane sheet, calculation/engine.py _out_of_plane_variants): heel_left/heel_right = 0.5 heel_point +/- M_heel / boom width (the app's split), platform base Fy/Mx with the sign of the applied loads; fradial = sqrt(Fx^2 + Fy^2), mradial = sqrt(Mx^2 + My^2), bearing line loads Fz/(pi D) +/- 4 mradial/(pi D^2) (min shows uplift only, core/demand_extraction.py); n/a without a bearing diameter (the app hides them).
A11: Status
A12: Results valid | B12: =IF(AND(Statics!$B$13=1,OutOfPlane!$B$21=1),1,0) | C12: 1/0 | D12: ok -- Statics ok and boom width > 0
A13: Short reason (shown in the value cells) | B13: =IF(Results!$B$12=1,"",IF(Statics!$B$10=0,"no solve rope",IF(OR(Statics!$B$11=1,Statics!$B$12=1),"singular matrix",IF(OutOfPlane!$B$21<>1,"boom width must be > 0","no solution")))) | D13: reason
A14: Status | B14: =IF(Results!$B$12=1,"OK",IF(Statics!$B$10=0,"No solve rope: no active rope has role solve (Inputs ropes), so the boom matrix is singular and the app shows no results",IF(OR(Statics!$B$11=1,Statics!$B$12=1),"Singular matrix on Statics (boom 3x3 or leg frame 6x6): the app finds no solution and shows no results",IF(OutOfPlane!$B$21<>1,"Boom width (Inputs structure) must be > 0: the app rejects it and its out-of-plane split divides by it, so it shows no results","No solution")))) | D14: message
A16: Rope tensions per hoist (row i = Inputs hoists row i)
A17: Active [1/0] | B17: Hoist | C17: Rope id | D17: Rope role | E17: Rope tension T [kN]
A18: active (from Inputs) | B18: hoist_id (result key tension.<hoist>) | C18: rope_id | D18: role ('' if the rope is missing) | E18: tension_kN
A19: =Inputs!$A$304 | B19: =IF(Results!$A$19=1,Inputs!$B$304&"","") | C19: =IF(Results!$A$19=1,Inputs!$C$304&"","") | D19: =IF(Results!$C$19="","",IFERROR(INDEX(Loads!$D$125:$D$132,MATCH(Results!$C$19,Loads!$C$125:$C$132,0))&"","")) | E19: =IF(Results!$A$19<>1,0,IF(Results!$B$12<>1,Results!$B$13,IF(Results!$D$19="solve",Statics!$H$37,IF(Results!$D$19="",0,INDEX(Loads!$K$125:$K$132,MATCH(Results!$C$19,Loads!$C$125:$C$132,0))))))
A20: =Inputs!$A$305 | B20: =IF(Results!$A$20=1,Inputs!$B$305&"","") | C20: =IF(Results!$A$20=1,Inputs!$C$305&"","") | D20: =IF(Results!$C$20="","",IFERROR(INDEX(Loads!$D$125:$D$132,MATCH(Results!$C$20,Loads!$C$125:$C$132,0))&"","")) | E20: =IF(Results!$A$20<>1,0,IF(Results!$B$12<>1,Results!$B$13,IF(Results!$D$20="solve",Statics!$H$37,IF(Results!$D$20="",0,INDEX(Loads!$K$125:$K$132,MATCH(Results!$C$20,Loads!$C$125:$C$132,0))))))
A21: =Inputs!$A$306 | B21: =IF(Results!$A$21=1,Inputs!$B$306&"","") | C21: =IF(Results!$A$21=1,Inputs!$C$306&"","") | D21: =IF(Results!$C$21="","",IFERROR(INDEX(Loads!$D$125:$D$132,MATCH(Results!$C$21,Loads!$C$125:$C$132,0))&"","")) | E21: =IF(Results!$A$21<>1,0,IF(Results!$B$12<>1,Results!$B$13,IF(Results!$D$21="solve",Statics!$H$37,IF(Results!$D$21="",0,INDEX(Loads!$K$125:$K$132,MATCH(Results!$C$21,Loads!$C$125:$C$132,0))))))
A22: =Inputs!$A$307 | B22: =IF(Results!$A$22=1,Inputs!$B$307&"","") | C22: =IF(Results!$A$22=1,Inputs!$C$307&"","") | D22: =IF(Results!$C$22="","",IFERROR(INDEX(Loads!$D$125:$D$132,MATCH(Results!$C$22,Loads!$C$125:$C$132,0))&"","")) | E22: =IF(Results!$A$22<>1,0,IF(Results!$B$12<>1,Results!$B$13,IF(Results!$D$22="solve",Statics!$H$37,IF(Results!$D$22="",0,INDEX(Loads!$K$125:$K$132,MATCH(Results!$C$22,Loads!$C$125:$C$132,0))))))
A23: =Inputs!$A$308 | B23: =IF(Results!$A$23=1,Inputs!$B$308&"","") | C23: =IF(Results!$A$23=1,Inputs!$C$308&"","") | D23: =IF(Results!$C$23="","",IFERROR(INDEX(Loads!$D$125:$D$132,MATCH(Results!$C$23,Loads!$C$125:$C$132,0))&"","")) | E23: =IF(Results!$A$23<>1,0,IF(Results!$B$12<>1,Results!$B$13,IF(Results!$D$23="solve",Statics!$H$37,IF(Results!$D$23="",0,INDEX(Loads!$K$125:$K$132,MATCH(Results!$C$23,Loads!$C$125:$C$132,0))))))
A24: =Inputs!$A$309 | B24: =IF(Results!$A$24=1,Inputs!$B$309&"","") | C24: =IF(Results!$A$24=1,Inputs!$C$309&"","") | D24: =IF(Results!$C$24="","",IFERROR(INDEX(Loads!$D$125:$D$132,MATCH(Results!$C$24,Loads!$C$125:$C$132,0))&"","")) | E24: =IF(Results!$A$24<>1,0,IF(Results!$B$12<>1,Results!$B$13,IF(Results!$D$24="solve",Statics!$H$37,IF(Results!$D$24="",0,INDEX(Loads!$K$125:$K$132,MATCH(Results!$C$24,Loads!$C$125:$C$132,0))))))
A25: =Inputs!$A$310 | B25: =IF(Results!$A$25=1,Inputs!$B$310&"","") | C25: =IF(Results!$A$25=1,Inputs!$C$310&"","") | D25: =IF(Results!$C$25="","",IFERROR(INDEX(Loads!$D$125:$D$132,MATCH(Results!$C$25,Loads!$C$125:$C$132,0))&"","")) | E25: =IF(Results!$A$25<>1,0,IF(Results!$B$12<>1,Results!$B$13,IF(Results!$D$25="solve",Statics!$H$37,IF(Results!$D$25="",0,INDEX(Loads!$K$125:$K$132,MATCH(Results!$C$25,Loads!$C$125:$C$132,0))))))
A26: =Inputs!$A$311 | B26: =IF(Results!$A$26=1,Inputs!$B$311&"","") | C26: =IF(Results!$A$26=1,Inputs!$C$311&"","") | D26: =IF(Results!$C$26="","",IFERROR(INDEX(Loads!$D$125:$D$132,MATCH(Results!$C$26,Loads!$C$125:$C$132,0))&"","")) | E26: =IF(Results!$A$26<>1,0,IF(Results!$B$12<>1,Results!$B$13,IF(Results!$D$26="solve",Statics!$H$37,IF(Results!$D$26="",0,INDEX(Loads!$K$125:$K$132,MATCH(Results!$C$26,Loads!$C$125:$C$132,0))))))
A30: Support reactions
A31: Result key | B31: Support | C31: Component | D31: Value | E31: Unit | F31: From
A32: key (reaction.<entity>.<component>) | B32: entity | C32: component | D32: value (kN or kNm, see unit) | E32: unit | F32: source
A33: reaction.heel_point.fx | B33: heel_point | C33: fx | D33: =IF(Results!$B$12<>1,Results!$B$13,Statics!$H$35) | E33: kN | F33: Statics Hx
A34: reaction.heel_point.fz | B34: heel_point | C34: fz | D34: =IF(Results!$B$12<>1,Results!$B$13,Statics!$H$36) | E34: kN | F34: Statics Hz
A35: reaction.heel_point.resultant | B35: heel_point | C35: resultant | D35: =IF(Results!$B$12<>1,Results!$B$13,SQRT(Statics!$H$35^2+Statics!$H$36^2)) | E35: kN | F35: sqrt(Fx^2 + Fz^2)
A36: reaction.front_hinge.fx | B36: front_hinge | C36: fx | D36: =IF(Results!$B$12<>1,Results!$B$13,Statics!$K$55) | E36: kN | F36: Statics R_fb_x
A37: reaction.front_hinge.fz | B37: front_hinge | C37: fz | D37: =IF(Results!$B$12<>1,Results!$B$13,Statics!$K$56) | E37: kN | F37: Statics R_fb_z
A38: reaction.front_hinge.resultant | B38: front_hinge | C38: resultant | D38: =IF(Results!$B$12<>1,Results!$B$13,SQRT(Statics!$K$55^2+Statics!$K$56^2)) | E38: kN | F38: sqrt(Fx^2 + Fz^2)
A39: reaction.front_hinge.leg_axial | B39: front_hinge | C39: leg_axial | D39: =IF(Results!$B$12<>1,Results!$B$13,IF(Statics!$B$83=1,Statics!$K$55*Statics!$B$81+Statics!$K$56*Statics!$B$82,"n/a (zero-length leg)")) | E39: kN | F39: Fx ux + Fz uz, front_base -> front_top
A40: reaction.front_hinge.leg_normal | B40: front_hinge | C40: leg_normal | D40: =IF(Results!$B$12<>1,Results!$B$13,IF(Statics!$B$83=1,-Statics!$K$55*Statics!$B$82+Statics!$K$56*Statics!$B$81,"n/a (zero-length leg)")) | E40: kN | F40: -Fx uz + Fz ux
A41: reaction.rear_hinge.fx | B41: rear_hinge | C41: fx | D41: =IF(Results!$B$12<>1,Results!$B$13,Statics!$K$53) | E41: kN | F41: Statics R_rb_x
A42: reaction.rear_hinge.fz | B42: rear_hinge | C42: fz | D42: =IF(Results!$B$12<>1,Results!$B$13,Statics!$K$54) | E42: kN | F42: Statics R_rb_z
A43: reaction.rear_hinge.resultant | B43: rear_hinge | C43: resultant | D43: =IF(Results!$B$12<>1,Results!$B$13,SQRT(Statics!$K$53^2+Statics!$K$54^2)) | E43: kN | F43: sqrt(Fx^2 + Fz^2)
A44: reaction.rear_hinge.leg_axial | B44: rear_hinge | C44: leg_axial | D44: =IF(Results!$B$12<>1,Results!$B$13,IF(Statics!$B$79=1,Statics!$K$53*Statics!$B$77+Statics!$K$54*Statics!$B$78,"n/a (zero-length leg)")) | E44: kN | F44: Fx ux + Fz uz, rear_base -> rear_top
A45: reaction.rear_hinge.leg_normal | B45: rear_hinge | C45: leg_normal | D45: =IF(Results!$B$12<>1,Results!$B$13,IF(Statics!$B$79=1,-Statics!$K$53*Statics!$B$78+Statics!$K$54*Statics!$B$77,"n/a (zero-length leg)")) | E45: kN | F45: -Fx uz + Fz ux
A46: reaction.upper_hinge.fx | B46: upper_hinge | C46: fx | D46: =IF(Results!$B$12<>1,Results!$B$13,Statics!$K$57) | E46: kN | F46: Statics R_top_x
A47: reaction.upper_hinge.fz | B47: upper_hinge | C47: fz | D47: =IF(Results!$B$12<>1,Results!$B$13,Statics!$K$58) | E47: kN | F47: Statics R_top_z
...

Sheet Checks
A1: Checks -- every count must be 0
B3: Total issues | C3: =SUM(C6:C20) | D3: =IF(C3=0,"OK","CHECK INPUTS")
A5: Check | B5: Description | C5: Count | D5: Status
A6: overflow | B6: Rows that do not fit a table (generator) or typed into a guard row | C6: =SUM($D$25:$D$30) | D6: =IF(C6=0,"OK","CHECK")
A7: duplicate_ids | B7: Active rows whose id is used by another active row of the same table | C7: =SUMPRODUCT((Inputs!$A$46:$A$85=1)*(Inputs!$B$46:$B$85<>"")*(COUNTIFS(Inputs!$B$46:$B$85,Inputs!$B$46:$B$85,Inputs!$A$46:$A$85,1)>1))+SUMPRODUCT((Inputs!$A$92:$A$131=1)*(Inputs!$B$92:$B$131<>"")*(COUNTIFS(Inputs!$B$92:$B$131,Inputs!$B$92:$B$131,Inputs!$A$92:$A$131,1)>1))+SUMPRODUCT((Inputs!$A$138:$A$217=1)*(Inputs!$B$138:$B$217<>"")*(COUNTIFS(Inputs!$B$138:$B$217,Inputs!$B$138:$B$217,Inputs!$A$138:$A$217,1)>1))+SUMPRODUCT((Inputs!$A$290:$A$297=1)*(Inputs!$B$290:$B$297<>"")*(COUNTIFS(Inputs!$B$290:$B$297,Inputs!$B$290:$B$297,Inputs!$A$290:$A$297,1)>1))+SUMPRODUCT((Inputs!$A$304:$A$311=1)*(Inputs!$B$304:$B$311<>"")*(COUNTIFS(Inputs!$B$304:$B$311,Inputs!$B$304:$B$311,Inputs!$A$304:$A$311,1)>1)) | D7: =IF(C7=0,"OK","CHECK")
A8: blank_ids | B8: Active rows with a blank id (or blank rope id on a segment) | C8: =SUMPRODUCT((Inputs!$A$46:$A$85=1)*(Inputs!$B$46:$B$85=""))+SUMPRODUCT((Inputs!$A$92:$A$131=1)*(Inputs!$B$92:$B$131=""))+SUMPRODUCT((Inputs!$A$138:$A$217=1)*(Inputs!$B$138:$B$217=""))+SUMPRODUCT((Inputs!$A$290:$A$297=1)*(Inputs!$B$290:$B$297=""))+SUMPRODUCT((Inputs!$A$304:$A$311=1)*(Inputs!$B$304:$B$311=""))+SUMPRODUCT((Inputs!$A$224:$A$283=1)*(Inputs!$B$224:$B$283="")) | D8: =IF(C8=0,"OK","CHECK")
A9: node_references | B9: References to a missing or inactive node (segment ends, hoist hook/support nodes, hanging nodes' parent) | C9: =SUMPRODUCT((Inputs!$A$224:$A$283=1)*(COUNTIFS(Inputs!$B$138:$B$217,Inputs!$C$224:$C$283,Inputs!$A$138:$A$217,1)=0))+SUMPRODUCT((Inputs!$A$224:$A$283=1)*(COUNTIFS(Inputs!$B$138:$B$217,Inputs!$D$224:$D$283,Inputs!$A$138:$A$217,1)=0))+SUMPRODUCT((Inputs!$A$304:$A$311=1)*(COUNTIFS(Inputs!$B$138:$B$217,Inputs!$D$304:$D$311,Inputs!$A$138:$A$217,1)=0))+SUMPRODUCT((Inputs!$A$304:$A$311=1)*(Inputs!$E$304:$E$311<>"")*(COUNTIFS(Inputs!$B$138:$B$217,Inputs!$E$304:$E$311,Inputs!$A$138:$A$217,1)=0))+SUMPRODUCT((Inputs!$A$138:$A$217=1)*(Inputs!$D$138:$D$217="hanging")*(COUNTIFS(Inputs!$B$138:$B$217,Inputs!$I$138:$I$217,Inputs!$A$138:$A$217,1)=0)) | D9: =IF(C9=0,"OK","CHECK")
A10: rope_references | B10: Segments or hoists referencing a missing or inactive rope | C10: =SUMPRODUCT((Inputs!$A$224:$A$283=1)*(COUNTIFS(Inputs!$B$290:$B$297,Inputs!$B$224:$B$283,Inputs!$A$290:$A$297,1)=0))+SUMPRODUCT((Inputs!$A$304:$A$311=1)*(COUNTIFS(Inputs!$B$290:$B$297,Inputs!$C$304:$C$311,Inputs!$A$290:$A$297,1)=0)) | D10: =IF(C10=0,"OK","CHECK")
A11: hoist_without_segments | B11: Active hoists whose rope has no active segment | C11: =SUMPRODUCT((Inputs!$A$304:$A$311=1)*(COUNTIFS(Inputs!$B$224:$B$283,Inputs!$C$304:$C$311,Inputs!$A$224:$A$283,1)=0)) | D11: =IF(C11=0,"OK","CHECK")
A12: multiple_solve_ropes | B12: Active solve ropes beyond the first (exactly one is allowed) | C12: =MAX(0,COUNTIFS(Inputs!$A$290:$A$297,1,Inputs!$C$290:$C$297,"solve")-1) | D12: =IF(C12=0,"OK","CHECK")
A13: no_solve_rope | B13: 1 if no active rope has role solve (the app shows no results then) | C13: =IF(COUNTIFS(Inputs!$A$290:$A$297,1,Inputs!$C$290:$C$297,"solve")=0,1,0) | D13: =IF(C13=0,"OK","CHECK")
A14: scene_hoist | B14: 1 if the scene hoist is not an active hoist with a fixed rope | C14: =IF(COUNTIFS(Inputs!$B$304:$B$311,Inputs!$B$26,Inputs!$A$304:$A$311,1)=0,1,IF(COUNTIFS(Inputs!$B$290:$B$297,INDEX(Inputs!$C$304:$C$311,MATCH(Inputs!$B$26,Inputs!$B$304:$B$311,0)),Inputs!$A$290:$A$297,1,Inputs!$C$290:$C$297,"fixed")=0,1,0)) | D14: =IF(C14=0,"OK","CHECK")
A15: wind_direction | B15: 1 if the scene wind direction is not +X, -X, +Y or -Y | C15: =IF(OR(Inputs!$B$33="+X",Inputs!$B$33="-X",Inputs!$B$33="+Y",Inputs!$B$33="-Y"),0,1) | D15: =IF(C15=0,"OK","CHECK")
A16: fixed_nodes_missing | B16: Fixed structure node ids with no active node row | C16: =COUNTIF($B$34:$B$42,0) | D16: =IF(C16=0,"OK","CHECK")
A17: hanging_chain | B17: Hanging nodes whose parent is itself hanging (only one level is resolved) | C17: =SUMPRODUCT((Inputs!$A$138:$A$217=1)*(Inputs!$D$138:$D$217="hanging")*(COUNTIFS(Inputs!$B$138:$B$217,Inputs!$I$138:$I$217,Inputs!$D$138:$D$217,"hanging",Inputs!$A$138:$A$217,1)>0)) | D17: =IF(C17=0,"OK","CHECK")
A18: singular_matrix | B18: Singular Statics systems (boom 3x3, leg frame 6x6); the boom one is singular without a solve rope | C18: =Statics!$B$41+Statics!$B$62 | D18: =IF(C18=0,"OK","CHECK")
A19: zero_boom_width | B19: 1 if the boom width is not > 0 (the app rejects it; the out-of-plane split divides by it, so Results shows a message) | C19: =IF(OutOfPlane!$B$21=1,0,1) | D19: =IF(C19=0,"OK","CHECK")
A20: invalid_bearing_diameter | B20: 1 if the slewing bearing diameter is typed but not a number > 0 (blank is allowed and hides the bearing line-load rows) | C20: =IF(Inputs!$B$13="",0,IF(ISNUMBER(Inputs!$B$13),IF(Inputs!$B$13>0,0,1),1)) | D20: =IF(C20=0,"OK","CHECK")
A23: Overflow per table
A24: Table | B24: Not written | C24: Typed in guard row | D24: Total
A25: mass_points | B25: =Inputs!$G$43 | C25: =COUNTA(Inputs!$A$86:$K$86) | D25: =B25+C25
A26: wind_areas | B26: =Inputs!$G$89 | C26: =COUNTA(Inputs!$A$132:$K$132) | D26: =B26+C26
A27: nodes | B27: =Inputs!$G$135 | C27: =COUNTA(Inputs!$A$218:$K$218) | D27: =B27+C27
A28: segments | B28: =Inputs!$G$221 | C28: =COUNTA(Inputs!$A$284:$E$284) | D28: =B28+C28
A29: ropes | B29: =Inputs!$G$287 | C29: =COUNTA(Inputs!$A$298:$C$298) | D29: =B29+C29
A30: hoists | B30: =Inputs!$G$301 | C30: =COUNTA(Inputs!$A$312:$Q$312) | D30: =B30+C30
A33: Fixed structure nodes (active rows with this id)
A34: boom_heel | B34: =COUNTIFS(Inputs!$B$138:$B$217,A34,Inputs!$A$138:$A$217,1)
A35: platform_heel | B35: =COUNTIFS(Inputs!$B$138:$B$217,A35,Inputs!$A$138:$A$217,1)
A36: rear_top | B36: =COUNTIFS(Inputs!$B$138:$B$217,A36,Inputs!$A$138:$A$217,1)
A37: front_top | B37: =COUNTIFS(Inputs!$B$138:$B$217,A37,Inputs!$A$138:$A$217,1)
A38: rear_base | B38: =COUNTIFS(Inputs!$B$138:$B$217,A38,Inputs!$A$138:$A$217,1)
A39: platform_rear | B39: =COUNTIFS(Inputs!$B$138:$B$217,A39,Inputs!$A$138:$A$217,1)
A40: front_base | B40: =COUNTIFS(Inputs!$B$138:$B$217,A40,Inputs!$A$138:$A$217,1)
A41: platform_front | B41: =COUNTIFS(Inputs!$B$138:$B$217,A41,Inputs!$A$138:$A$217,1)
A42: platform_base | B42: =COUNTIFS(Inputs!$B$138:$B$217,A42,Inputs!$A$138:$A$217,1)
